Workbook

Sheet Instructions
A1: ALAS Energy | Portfolio Control Workbook
A2: Weighted renewable project control model with checklist logic, risk adjustment, budget control, and geography rollups.
A4: Step | B4: Area | C4: Explanation
A5: 1 | B5: Update status | C5: In Task_Tracker, switch Status between ☑ and ☐. Completion_Value updates automatically.
A6: 2 | B6: Review timing | C6: Planned_Date is the scheduled milestone. Actual_Date reflects realized completion for done tasks.
A7: 3 | B7: Use controller KPIs | C7: Portfolio_Master calculates Progress %, Total Delay Impact, Risk Factor, Risk-Adjusted Progress, Budget Used %, and Efficiency Index.
A8: 4 | B8: Read geography rollups | C8: Geography_Progress shows weighted progress by country first, then state, with progress bars.
A9: 5 | B9: Present the story | C9: Dashboard turns the tracker into a control tower view for interviews, outreach, or a reel.
A11: Source note | B11: Aligned to ILOS Energy's renewable project lifecycle and project control needs.

Sheet Task_Tracker
A1: ALAS Energy | Task Tracker
A2: Weighted milestones with timing and delay logic. This is the engine that drives all portfolio, country, and state progress calculations.
A4: Project_ID | B4: Project_Name | C4: Country | D4: State | E4: Task_Name | F4: Stage | G4: Owner | H4: Status | I4: Weight | J4: Completion_Value | K4: Planned_Date | L4: Actual_Date | M4: Delay_Days | N4: Delay_Impact | O4: Risk_Level | P4: Critical_Flag
A5: P-101 | B5: Brandenburg Solar Park | C5: Germany | D5: Brandenburg | E5: Land Secured | F5: Development | G5: Development Lead | H5: ☑ | I5: 8 | J5: =IF(H5="☑",I5,0) -> 8 | K5: 45933 | L5: 45933 | M5: =IF(H5="☑",MAX(0,L5-K5),MAX(0,TODAY()-K5)) -> 0 | N5: =M5*I5 -> 0 | O5: =IF(N5>80,"High",IF(N5>40,"Medium","Low")) -> Low | P5: No
A6: P-101 | B6: Brandenburg Solar Park | C6: Germany | D6: Brandenburg | E6: Grid Connection Secured | F6: Development | G6: Grid Manager | H6: ☑ | I6: 10 | J6: =IF(H6="☑",I6,0) -> 10 | K6: 45973 | L6: 45975 | M6: =IF(H6="☑",MAX(0,L6-K6),MAX(0,TODAY()-K6)) -> 2 | N6: =M6*I6 -> 20 | O6: =IF(N6>80,"High",IF(N6>40,"Medium","Low")) -> Low | P6: Yes
A7: P-101 | B7: Brandenburg Solar Park | C7: Germany | D7: Brandenburg | E7: Permit Approved | F7: Development | G7: Permitting Manager | H7: ☑ | I7: 12 | J7: =IF(H7="☑",I7,0) -> 12 | K7: 46013 | L7: 46018 | M7: =IF(H7="☑",MAX(0,L7-K7),MAX(0,TODAY()-K7)) -> 5 | N7: =M7*I7 -> 60 | O7: =IF(N7>80,"High",IF(N7>40,"Medium","Low")) -> Medium | P7: Yes
A8: P-101 | B8: Brandenburg Solar Park | C8: Germany | D8: Brandenburg | E8: Environmental Review Closed | F8: Development | G8: ESG & Compliance | H8: ☑ | I8: 6 | J8: =IF(H8="☑",I8,0) -> 6 | K8: 46053 | L8: 46056 | M8: =IF(H8="☑",MAX(0,L8-K8),MAX(0,TODAY()-K8)) -> 3 | N8: =M8*I8 -> 18 | O8: =IF(N8>80,"High",IF(N8>40,"Medium","Low")) -> Low | P8: No
A9: P-101 | B9: Brandenburg Solar Park | C9: Germany | D9: Brandenburg | E9: EPC Assigned | F9: Construction | G9: Construction Manager | H9: ☑ | I9: 8 | J9: =IF(H9="☑",I9,0) -> 8 | K9: 46093 | L9: 46097 | M9: =IF(H9="☑",MAX(0,L9-K9),MAX(0,TODAY()-K9)) -> 4 | N9: =M9*I9 -> 32 | O9: =IF(N9>80,"High",IF(N9>40,"Medium","Low")) -> Low | P9: No
A10: P-101 | B10: Brandenburg Solar Park | C10: Germany | D10: Brandenburg | E10: Equipment Delivered | F10: Construction | G10: Supply Chain Lead | H10: ☑ | I10: 10 | J10: =IF(H10="☑",I10,0) -> 10 | K10: 46143 | L10: 46149 | M10: =IF(H10="☑",MAX(0,L10-K10),MAX(0,TODAY()-K10)) -> 6 | N10: =M10*I10 -> 60 | O10: =IF(N10>80,"High",IF(N10>40,"Medium","Low")) -> Medium | P10: Yes
A11: P-101 | B11: Brandenburg Solar Park | C11: Germany | D11: Brandenburg | E11: Installation Started | F11: Construction | G11: Site Manager | H11: ☑ | I11: 10 | J11: =IF(H11="☑",I11,0) -> 10 | K11: 46163 | L11: 46170 | M11: =IF(H11="☑",MAX(0,L11-K11),MAX(0,TODAY()-K11)) -> 7 | N11: =M11*I11 -> 70 | O11: =IF(N11>80,"High",IF(N11>40,"Medium","Low")) -> Medium | P11: Yes
A12: P-101 | B12: Brandenburg Solar Park | C12: Germany | D12: Brandenburg | E12: Installation Completed | F12: Construction | G12: Site Manager | H12: ☐ | I12: 12 | J12: =IF(H12="☑",I12,0) -> 0 | K12: 46203 | M12: =IF(H12="☑",MAX(0,L12-K12),MAX(0,TODAY()-K12)) -> 0 | N12: =M12*I12 -> 0 | O12: =IF(N12>80,"High",IF(N12>40,"Medium","Low")) -> Low | P12: Yes
A13: P-101 | B13: Brandenburg Solar Park | C13: Germany | D13: Brandenburg | E13: Testing Completed | F13: Commissioning | G13: Commissioning Engineer | H13: ☐ | I13: 10 | J13: =IF(H13="☑",I13,0) -> 0 | K13: 46223 | M13: =IF(H13="☑",MAX(0,L13-K13),MAX(0,TODAY()-K13)) -> 0 | N13: =M13*I13 -> 0 | O13: =IF(N13>80,"High",IF(N13>40,"Medium","Low")) -> Low | P13: Yes
A14: P-101 | B14: Brandenburg Solar Park | C14: Germany | D14: Brandenburg | E14: Project Activated | F14: Commissioning | G14: Asset Manager | H14: ☐ | I14: 14 | J14: =IF(H14="☑",I14,0) -> 0 | K14: 46233 | M14: =IF(H14="☑",MAX(0,L14-K14),MAX(0,TODAY()-K14)) -> 0 | N14: =M14*I14 -> 0 | O14: =IF(N14>80,"High",IF(N14>40,"Medium","Low")) -> Low | P14: Yes
A15: P-102 | B15: Andalusia Solar Cluster | C15: Spain | D15: Andalusia | E15: Land Secured | F15: Development | G15: Development Lead | H15: ☑ | I15: 8 | J15: =IF(H15="☑",I15,0) -> 8 | K15: 45980 | L15: 45980 | M15: =IF(H15="☑",MAX(0,L15-K15),MAX(0,TODAY()-K15)) -> 0 | N15: =M15*I15 -> 0 | O15: =IF(N15>80,"High",IF(N15>40,"Medium","Low")) -> Low | P15: No
A16: P-102 | B16: Andalusia Solar Cluster | C16: Spain | D16: Andalusia | E16: Grid Connection Secured | F16: Development | G16: Grid Manager | H16: ☑ | I16: 10 | J16: =IF(H16="☑",I16,0) -> 10 | K16: 46020 | L16: 46020 | M16: =IF(H16="☑",MAX(0,L16-K16),MAX(0,TODAY()-K16)) -> 0 | N16: =M16*I16 -> 0 | O16: =IF(N16>80,"High",IF(N16>40,"Medium","Low")) -> Low | P16: Yes
A17: P-102 | B17: Andalusia Solar Cluster | C17: Spain | D17: Andalusia | E17: Permit Approved | F17: Development | G17: Permitting Manager | H17: ☑ | I17: 12 | J17: =IF(H17="☑",I17,0) -> 12 | K17: 46060 | L17: 46061 | M17: =IF(H17="☑",MAX(0,L17-K17),MAX(0,TODAY()-K17)) -> 1 | N17: =M17*I17 -> 12 | O17: =IF(N17>80,"High",IF(N17>40,"Medium","Low")) -> Low | P17: Yes
A18: P-102 | B18: Andalusia Solar Cluster | C18: Spain | D18: Andalusia | E18: Environmental Review Closed | F18: Development | G18: ESG & Compliance | H18: ☑ | I18: 6 | J18: =IF(H18="☑",I18,0) -> 6 | K18: 46100 | L18: 46102 | M18: =IF(H18="☑",MAX(0,L18-K18),MAX(0,TODAY()-K18)) -> 2 | N18: =M18*I18 -> 12 | O18: =IF(N18>80,"High",IF(N18>40,"Medium","Low")) -> Low | P18: No
A19: P-102 | B19: Andalusia Solar Cluster | C19: Spain | D19: Andalusia | E19: EPC Assigned | F19: Construction | G19: Construction Manager | H19: ☑ | I19: 8 | J19: =IF(H19="☑",I19,0) -> 8 | K19: 46140 | L19: 46144 | M19: =IF(H19="☑",MAX(0,L19-K19),MAX(0,TODAY()-K19)) -> 4 | N19: =M19*I19 -> 32 | O19: =IF(N19>80,"High",IF(N19>40,"Medium","Low")) -> Low | P19: No
A20: P-102 | B20: Andalusia Solar Cluster | C20: Spain | D20: Andalusia | E20: Equipment Delivered | F20: Construction | G20: Supply Chain Lead | H20: ☑ | I20: 10 | J20: =IF(H20="☑",I20,0) -> 10 | K20: 46190 | L20: 46196 | M20: =IF(H20="☑",MAX(0,L20-K20),MAX(0,TODAY()-K20)) -> 6 | N20: =M20*I20 -> 60 | O20: =IF(N20>80,"High",IF(N20>40,"Medium","Low")) -> Medium | P20: Yes
A21: P-102 | B21: Andalusia Solar Cluster | C21: Spain | D21: Andalusia | E21: Installation Started | F21: Construction | G21: Site Manager | H21: ☐ | I21: 10 | J21: =IF(H21="☑",I21,0) -> 0 | K21: 46210 | M21: =IF(H21="☑",MAX(0,L21-K21),MAX(0,TODAY()-K21)) -> 0 | N21: =M21*I21 -> 0 | O21: =IF(N21>80,"High",IF(N21>40,"Medium","Low")) -> Low | P21: Yes
A22: P-102 | B22: Andalusia Solar Cluster | C22: Spain | D22: Andalusia | E22: Installation Completed | F22: Construction | G22: Site Manager | H22: ☐ | I22: 12 | J22: =IF(H22="☑",I22,0) -> 0 | K22: 46250 | M22: =IF(H22="☑",MAX(0,L22-K22),MAX(0,TODAY()-K22)) -> 0 | N22: =M22*I22 -> 0 | O22: =IF(N22>80,"High",IF(N22>40,"Medium","Low")) -> Low | P22: Yes
A23: P-102 | B23: Andalusia Solar Cluster | C23: Spain | D23: Andalusia | E23: Testing Completed | F23: Commissioning | G23: Commissioning Engineer | H23: ☐ | I23: 10 | J23: =IF(H23="☑",I23,0) -> 0 | K23: 46270 | M23: =IF(H23="☑",MAX(0,L23-K23),MAX(0,TODAY()-K23)) -> 0 | N23: =M23*I23 -> 0 | O23: =IF(N23>80,"High",IF(N23>40,"Medium","Low")) -> Low | P23: Yes
A24: P-102 | B24: Andalusia Solar Cluster | C24: Spain | D24: Andalusia | E24: Project Activated | F24: Commissioning | G24: Asset Manager | H24: ☐ | I24: 14 | J24: =IF(H24="☑",I24,0) -> 0 | K24: 46280 | M24: =IF(H24="☑",MAX(0,L24-K24),MAX(0,TODAY()-K24)) -> 0 | N24: =M24*I24 -> 0 | O24: =IF(N24>80,"High",IF(N24>40,"Medium","Low")) -> Low | P24: Yes
A25: P-103 | B25: Sicily Agrivoltaic Hub | C25: Italy | D25: Sicily | E25: Land Secured | F25: Development | G25: Development Lead | H25: ☑ | I25: 8 | J25: =IF(H25="☑",I25,0) -> 8 | K25: 46005 | L25: 46005 | M25: =IF(H25="☑",MAX(0,L25-K25),MAX(0,TODAY()-K25)) -> 0 | N25: =M25*I25 -> 0 | O25: =IF(N25>80,"High",IF(N25>40,"Medium","Low")) -> Low | P25: No
A26: P-103 | B26: Sicily Agrivoltaic Hub | C26: Italy | D26: Sicily | E26: Grid Connection Secured | F26: Development | G26: Grid Manager | H26: ☑ | I26: 10 | J26: =IF(H26="☑",I26,0) -> 10 | K26: 46045 | L26: 46046 | M26: =IF(H26="☑",MAX(0,L26-K26),MAX(0,TODAY()-K26)) -> 1 | N26: =M26*I26 -> 10 | O26: =IF(N26>80,"High",IF(N26>40,"Medium","Low")) -> Low | P26: Yes
A27: P-103 | B27: Sicily Agrivoltaic Hub | C27: Italy | D27: Sicily | E27: Permit Approved | F27: Development | G27: Permitting Manager | H27: ☑ | I27: 12 | J27: =IF(H27="☑",I27,0) -> 12 | K27: 46085 | L27: 46087 | M27: =IF(H27="☑",MAX(0,L27-K27),MAX(0,TODAY()-K27)) -> 2 | N27: =M27*I27 -> 24 | O27: =IF(N27>80,"High",IF(N27>40,"Medium","Low")) -> Low | P27: Yes
A28: P-103 | B28: Sicily Agrivoltaic Hub | C28: Italy | D28: Sicily | E28: Environmental Review Closed | F28: Development | G28: ESG & Compliance | H28: ☑ | I28: 6 | J28: =IF(H28="☑",I28,0) -> 6 | K28: 46125 | L28: 46126 | M28: =IF(H28="☑",MAX(0,L28-K28),MAX(0,TODAY()-K28)) -> 1 | N28: =M28*I28 -> 6 | O28: =IF(N28>80,"High",IF(N28>40,"Medium","Low")) -> Low | P28: No
A29: P-103 | B29: Sicily Agrivoltaic Hub | C29: Italy | D29: Sicily | E29: EPC Assigned | F29: Construction | G29: Construction Manager | H29: ☑ | I29: 8 | J29: =IF(H29="☑",I29,0) -> 8 | K29: 46165 | L29: 46167 | M29: =IF(H29="☑",MAX(0,L29-K29),MAX(0,TODAY()-K29)) -> 2 | N29: =M29*I29 -> 16 | O29: =IF(N29>80,"High",IF(N29>40,"Medium","Low")) -> Low | P29: No
A30: P-103 | B30: Sicily Agrivoltaic Hub | C30: Italy | D30: Sicily | E30: Equipment Delivered | F30: Construction | G30: Supply Chain Lead | H30: ☐ | I30: 10 | J30: =IF(H30="☑",I30,0) -> 0 | K30: 46215 | M30: =IF(H30="☑",MAX(0,L30-K30),MAX(0,TODAY()-K30)) -> 0 | N30: =M30*I30 -> 0 | O30: =IF(N30>80,"High",IF(N30>40,"Medium","Low")) -> Low | P30: Yes
A31: P-103 | B31: Sicily Agrivoltaic Hub | C31: Italy | D31: Sicily | E31: Installation Started | F31: Construction | G31: Site Manager | H31: ☐ | I31: 10 | J31: =IF(H31="☑",I31,0) -> 0 | K31: 46235 | M31: =IF(H31="☑",MAX(0,L31-K31),MAX(0,TODAY()-K31)) -> 0 | N31: =M31*I31 -> 0 | O31: =IF(N31>80,"High",IF(N31>40,"Medium","Low")) -> Low | P31: Yes
A32: P-103 | B32: Sicily Agrivoltaic Hub | C32: Italy | D32: Sicily | E32: Installation Completed | F32: Construction | G32: Site Manager | H32: ☐ | I32: 12 | J32: =IF(H32="☑",I32,0) -> 0 | K32: 46275 | M32: =IF(H32="☑",MAX(0,L32-K32),MAX(0,TODAY()-K32)) -> 0 | N32: =M32*I32 -> 0 | O32: =IF(N32>80,"High",IF(N32>40,"Medium","Low")) -> Low | P32: Yes
A33: P-103 | B33: Sicily Agrivoltaic Hub | C33: Italy | D33: Sicily | E33: Testing Completed | F33: Commissioning | G33: Commissioning Engineer | H33: ☐ | I33: 10 | J33: =IF(H33="☑",I33,0) -> 0 | K33: 46295 | M33: =IF(H33="☑",MAX(0,L33-K33),MAX(0,TODAY()-K33)) -> 0 | N33: =M33*I33 -> 0 | O33: =IF(N33>80,"High",IF(N33>40,"Medium","Low")) -> Low | P33: Yes
A34: P-103 | B34: Sicily Agrivoltaic Hub | C34: Italy | D34: Sicily | E34: Project Activated | F34: Commissioning | G34: Asset Manager | H34: ☐ | I34: 14 | J34: =IF(H34="☑",I34,0) -> 0 | K34: 46305 | M34: =IF(H34="☑",MAX(0,L34-K34),MAX(0,TODAY()-K34)) -> 0 | N34: =M34*I34 -> 0 | O34: =IF(N34>80,"High",IF(N34>40,"Medium","Low")) -> Low | P34: Yes
A35: P-104 | B35: Occitanie Ground Mount | C35: France | D35: Occitanie | E35: Land Secured | F35: Development | G35: Development Lead | H35: ☑ | I35: 8 | J35: =IF(H35="☑",I35,0) -> 8 | K35: 45782 | L35: 45782 | M35: =IF(H35="☑",MAX(0,L35-K35),MAX(0,TODAY()-K35)) -> 0 | N35: =M35*I35 -> 0 | O35: =IF(N35>80,"High",IF(N35>40,"Medium","Low")) -> Low | P35: No
A36: P-104 | B36: Occitanie Ground Mount | C36: France | D36: Occitanie | E36: Grid Connection Secured | F36: Development | G36: Grid Manager | H36: ☑ | I36: 10 | J36: =IF(H36="☑",I36,0) -> 10 | K36: 45822 | L36: 45822 | M36: =IF(H36="☑",MAX(0,L36-K36),MAX(0,TODAY()-K36)) -> 0 | N36: =M36*I36 -> 0 | O36: =IF(N36>80,"High",IF(N36>40,"Medium","Low")) -> Low | P36: Yes
A37: P-104 | B37: Occitanie Ground Mount | C37: France | D37: Occitanie | E37: Permit Approved | F37: Development | G37: Permitting Manager | H37: ☑ | I37: 12 | J37: =IF(H37="☑",I37,0) -> 12 | K37: 45862 | L37: 45862 | M37: =IF(H37="☑",MAX(0,L37-K37),MAX(0,TODAY()-K37)) -> 0 | N37: =M37*I37 -> 0 | O37: =IF(N37>80,"High",IF(N37>40,"Medium","Low")) -> Low | P37: Yes
A38: P-104 | B38: Occitanie Ground Mount | C38: France | D38: Occitanie | E38: Environmental Review Closed | F38: Development | G38: ESG & Compliance | H38: ☑ | I38: 6 | J38: =IF(H38="☑",I38,0) -> 6 | K38: 45902 | L38: 45902 | M38: =IF(H38="☑",MAX(0,L38-K38),MAX(0,TODAY()-K38)) -> 0 | N38: =M38*I38 -> 0 | O38: =IF(N38>80,"High",IF(N38>40,"Medium","Low")) -> Low | P38: No
A39: P-104 | B39: Occitanie Ground Mount | C39: France | D39: Occitanie | E39: EPC Assigned | F39: Construction | G39: Construction Manager | H39: ☑ | I39: 8 | J39: =IF(H39="☑",I39,0) -> 8 | K39: 45942 | L39: 45944 | M39: =IF(H39="☑",MAX(0,L39-K39),MAX(0,TODAY()-K39)) -> 2 | N39: =M39*I39 -> 16 | O39: =IF(N39>80,"High",IF(N39>40,"Medium","Low")) -> Low | P39: No
A40: P-104 | B40: Occitanie Ground Mount | C40: France | D40: Occitanie | E40: Equipment Delivered | F40: Construction | G40: Supply Chain Lead | H40: ☑ | I40: 10 | J40: =IF(H40="☑",I40,0) -> 10 | K40: 45992 | L40: 45993 | M40: =IF(H40="☑",MAX(0,L40-K40),MAX(0,TODAY()-K40)) -> 1 | N40: =M40*I40 -> 10 | O40: =IF(N40>80,"High",IF(N40>40,"Medium","Low")) -> Low | P40: Yes
A41: P-104 | B41: Occitanie Ground Mount | C41: France | D41: Occitanie | E41: Installation Started | F41: Construction | G41: Site Manager | H41: ☑ | I41: 10 | J41: =IF(H41="☑",I41,0) -> 10 | K41: 46012 | L41: 46012 | M41: =IF(H41="☑",MAX(0,L41-K41),MAX(0,TODAY()-K41)) -> 0 | N41: =M41*I41 -> 0 | O41: =IF(N41>80,"High",IF(N41>40,"Medium","Low")) -> Low | P41: Yes
...

Sheet Portfolio_Master
A1: ALAS Energy | Portfolio Master
A2: Project-level control logic for progress, delay impact, risk adjustment, and budget-performance comparison.
A4: Project_ID | B4: Project_Name | C4: Country | D4: State | E4: Capacity_MW | F4: Stage | G4: Planned_COD | H4: Completed_Weight | I4: Total_Weight | J4: Progress_% | K4: Total_Delay_Impact | L4: Avg_Delay_Days | M4: Risk_Level | N4: Risk_Factor | O4: Risk_Adjusted_Progress | P4: Budget_M€ | Q4: Actual_Cost_M€ | R4: Budget_Used_% | S4: Efficiency_Index | T4: Budget_Alert
A5: P-101 | B5: Brandenburg Solar Park | C5: Germany | D5: Brandenburg | E5: 145 | F5: Development | G5: 46233 | H5: =SUMIF(Task_Tracker!$A$5:$A$84,A5,Task_Tracker!$J$5:$J$84) -> 64 | I5: =SUMIF(Task_Tracker!$A$5:$A$84,A5,Task_Tracker!$I$5:$I$84) -> 100 | J5: =IFERROR(H5/I5,0) -> 0.64 | K5: =SUMIF(Task_Tracker!$A$5:$A$84,A5,Task_Tracker!$N$5:$N$84) -> 260 | L5: =IFERROR(AVERAGEIF(Task_Tracker!$A$5:$A$84,A5,Task_Tracker!$M$5:$M$84),0) -> 2.7 | M5: =IF(K5>120,"High",IF(K5>45,"Medium","Low")) -> High | N5: =IF(M5="High",0.75,IF(M5="Medium",0.9,1)) -> 0.75 | O5: =J5*N5 -> 0.48 | P5: 120 | Q5: 114 | R5: =IFERROR(Q5/P5,0) -> 0.95 | S5: =IFERROR(J5/R5,0) -> 0.67368421 | T5: =IF(J5<R5,"Over Budget","On Track") -> Over Budget
A6: P-102 | B6: Andalusia Solar Cluster | C6: Spain | D6: Andalusia | E6: 220 | F6: Construction | G6: 46280 | H6: =SUMIF(Task_Tracker!$A$5:$A$84,A6,Task_Tracker!$J$5:$J$84) -> 54 | I6: =SUMIF(Task_Tracker!$A$5:$A$84,A6,Task_Tracker!$I$5:$I$84) -> 100 | J6: =IFERROR(H6/I6,0) -> 0.54 | K6: =SUMIF(Task_Tracker!$A$5:$A$84,A6,Task_Tracker!$N$5:$N$84) -> 116 | L6: =IFERROR(AVERAGEIF(Task_Tracker!$A$5:$A$84,A6,Task_Tracker!$M$5:$M$84),0) -> 1.3 | M6: =IF(K6>120,"High",IF(K6>45,"Medium","Low")) -> Medium | N6: =IF(M6="High",0.75,IF(M6="Medium",0.9,1)) -> 0.9 | O6: =J6*N6 -> 0.486 | P6: 165 | Q6: 172 | R6: =IFERROR(Q6/P6,0) -> 1.0424242 | S6: =IFERROR(J6/R6,0) -> 0.51802326 | T6: =IF(J6<R6,"Over Budget","On Track") -> Over Budget
A7: P-103 | B7: Sicily Agrivoltaic Hub | C7: Italy | D7: Sicily | E7: 110 | F7: Construction | G7: 46305 | H7: =SUMIF(Task_Tracker!$A$5:$A$84,A7,Task_Tracker!$J$5:$J$84) -> 44 | I7: =SUMIF(Task_Tracker!$A$5:$A$84,A7,Task_Tracker!$I$5:$I$84) -> 100 | J7: =IFERROR(H7/I7,0) -> 0.44 | K7: =SUMIF(Task_Tracker!$A$5:$A$84,A7,Task_Tracker!$N$5:$N$84) -> 56 | L7: =IFERROR(AVERAGEIF(Task_Tracker!$A$5:$A$84,A7,Task_Tracker!$M$5:$M$84),0) -> 0.6 | M7: =IF(K7>120,"High",IF(K7>45,"Medium","Low")) -> Medium | N7: =IF(M7="High",0.75,IF(M7="Medium",0.9,1)) -> 0.9 | O7: =J7*N7 -> 0.396 | P7: 94 | Q7: 98 | R7: =IFERROR(Q7/P7,0) -> 1.0425532 | S7: =IFERROR(J7/R7,0) -> 0.42204082 | T7: =IF(J7<R7,"Over Budget","On Track") -> Over Budget
A8: P-104 | B8: Occitanie Ground Mount | C8: France | D8: Occitanie | E8: 95 | F8: Active | G8: 46082 | H8: =SUMIF(Task_Tracker!$A$5:$A$84,A8,Task_Tracker!$J$5:$J$84) -> 100 | I8: =SUMIF(Task_Tracker!$A$5:$A$84,A8,Task_Tracker!$I$5:$I$84) -> 100 | J8: =IFERROR(H8/I8,0) -> 1 | K8: =SUMIF(Task_Tracker!$A$5:$A$84,A8,Task_Tracker!$N$5:$N$84) -> 26 | L8: =IFERROR(AVERAGEIF(Task_Tracker!$A$5:$A$84,A8,Task_Tracker!$M$5:$M$84),0) -> 0.3 | M8: =IF(K8>120,"High",IF(K8>45,"Medium","Low")) -> Low | N8: =IF(M8="High",0.75,IF(M8="Medium",0.9,1)) -> 1 | O8: =J8*N8 -> 1 | P8: 82 | Q8: 81 | R8: =IFERROR(Q8/P8,0) -> 0.98780488 | S8: =IFERROR(J8/R8,0) -> 1.0123457 | T8: =IF(J8<R8,"Over Budget","On Track") -> On Track
A9: P-105 | B9: North Holland Solar Farm | C9: Netherlands | D9: North Holland | E9: 80 | F9: Development | G9: 46254 | H9: =SUMIF(Task_Tracker!$A$5:$A$84,A9,Task_Tracker!$J$5:$J$84) -> 30 | I9: =SUMIF(Task_Tracker!$A$5:$A$84,A9,Task_Tracker!$I$5:$I$84) -> 100 | J9: =IFERROR(H9/I9,0) -> 0.3 | K9: =SUMIF(Task_Tracker!$A$5:$A$84,A9,Task_Tracker!$N$5:$N$84) -> 640 | L9: =IFERROR(AVERAGEIF(Task_Tracker!$A$5:$A$84,A9,Task_Tracker!$M$5:$M$84),0) -> 9.5 | M9: =IF(K9>120,"High",IF(K9>45,"Medium","Low")) -> High | N9: =IF(M9="High",0.75,IF(M9="Medium",0.9,1)) -> 0.75 | O9: =J9*N9 -> 0.225 | P9: 68 | Q9: 67 | R9: =IFERROR(Q9/P9,0) -> 0.98529412 | S9: =IFERROR(J9/R9,0) -> 0.30447761 | T9: =IF(J9<R9,"Over Budget","On Track") -> Over Budget
A10: P-106 | B10: Lower Silesia PV Project | C10: Poland | D10: Lower Silesia | E10: 130 | F10: Construction | G10: 46331 | H10: =SUMIF(Task_Tracker!$A$5:$A$84,A10,Task_Tracker!$J$5:$J$84) -> 44 | I10: =SUMIF(Task_Tracker!$A$5:$A$84,A10,Task_Tracker!$I$5:$I$84) -> 100 | J10: =IFERROR(H10/I10,0) -> 0.44 | K10: =SUMIF(Task_Tracker!$A$5:$A$84,A10,Task_Tracker!$N$5:$N$84) -> 34 | L10: =IFERROR(AVERAGEIF(Task_Tracker!$A$5:$A$84,A10,Task_Tracker!$M$5:$M$84),0) -> 0.4 | M10: =IF(K10>120,"High",IF(K10>45,"Medium","Low")) -> Low | N10: =IF(M10="High",0.75,IF(M10="Medium",0.9,1)) -> 1 | O10: =J10*N10 -> 0.44 | P10: 101 | Q10: 108 | R10: =IFERROR(Q10/P10,0) -> 1.0693069 | S10: =IFERROR(J10/R10,0) -> 0.41148148 | T10: =IF(J10<R10,"Over Budget","On Track") -> Over Budget
A11: P-107 | B11: Saxony Battery-Ready PV | C11: Germany | D11: Saxony | E11: 160 | F11: Development | G11: 46371 | H11: =SUMIF(Task_Tracker!$A$5:$A$84,A11,Task_Tracker!$J$5:$J$84) -> 36 | I11: =SUMIF(Task_Tracker!$A$5:$A$84,A11,Task_Tracker!$I$5:$I$84) -> 100 | J11: =IFERROR(H11/I11,0) -> 0.36 | K11: =SUMIF(Task_Tracker!$A$5:$A$84,A11,Task_Tracker!$N$5:$N$84) -> 46 | L11: =IFERROR(AVERAGEIF(Task_Tracker!$A$5:$A$84,A11,Task_Tracker!$M$5:$M$84),0) -> 0.5 | M11: =IF(K11>120,"High",IF(K11>45,"Medium","Low")) -> Medium | N11: =IF(M11="High",0.75,IF(M11="Medium",0.9,1)) -> 0.9 | O11: =J11*N11 -> 0.324 | P11: 126 | Q11: 123 | R11: =IFERROR(Q11/P11,0) -> 0.97619048 | S11: =IFERROR(J11/R11,0) -> 0.36878049 | T11: =IF(J11<R11,"Over Budget","On Track") -> Over Budget
A12: P-108 | B12: Valencia Hybrid Solar Site | C12: Spain | D12: Valencia | E12: 175 | F12: Active | G12: 46063 | H12: =SUMIF(Task_Tracker!$A$5:$A$84,A12,Task_Tracker!$J$5:$J$84) -> 100 | I12: =SUMIF(Task_Tracker!$A$5:$A$84,A12,Task_Tracker!$I$5:$I$84) -> 100 | J12: =IFERROR(H12/I12,0) -> 1 | K12: =SUMIF(Task_Tracker!$A$5:$A$84,A12,Task_Tracker!$N$5:$N$84) -> 20 | L12: =IFERROR(AVERAGEIF(Task_Tracker!$A$5:$A$84,A12,Task_Tracker!$M$5:$M$84),0) -> 0.2 | M12: =IF(K12>120,"High",IF(K12>45,"Medium","Low")) -> Low | N12: =IF(M12="High",0.75,IF(M12="Medium",0.9,1)) -> 1 | O12: =J12*N12 -> 1 | P12: 136 | Q12: 134 | R12: =IFERROR(Q12/P12,0) -> 0.98529412 | S12: =IFERROR(J12/R12,0) -> 1.0149254 | T12: =IF(J12<R12,"Over Budget","On Track") -> On Track

Sheet Geography_Progress
A1: ALAS Energy | Geography Progress
A3: Country Progress
A4: Country | B4: Projects | C4: Completed_Weight | D4: Total_Weight | E4: Weighted_Progress_% | F4: MW_Pipeline | G4: Delayed_Projects | H4: Progress_Bar
A5: France | B5: =COUNTIF(Portfolio_Master!$C$5:$C$12,A5) -> 1 | C5: =SUMIF(Portfolio_Master!$C$5:$C$12,A5,Portfolio_Master!$H$5:$H$12) -> 100 | D5: =SUMIF(Portfolio_Master!$C$5:$C$12,A5,Portfolio_Master!$I$5:$I$12) -> 100 | E5: =IFERROR(C5/D5,0) -> 1 | F5: =SUMIF(Portfolio_Master!$C$5:$C$12,A5,Portfolio_Master!$E$5:$E$12) -> 95 | G5: =COUNTIFS(Portfolio_Master!$C$5:$C$12,A5,Portfolio_Master!$M$5:$M$12,"<>Low") -> 0 | H5: =REPT("█",ROUND(E5*20,0)) -> ████████████████████
A6: Germany | B6: =COUNTIF(Portfolio_Master!$C$5:$C$12,A6) -> 2 | C6: =SUMIF(Portfolio_Master!$C$5:$C$12,A6,Portfolio_Master!$H$5:$H$12) -> 100 | D6: =SUMIF(Portfolio_Master!$C$5:$C$12,A6,Portfolio_Master!$I$5:$I$12) -> 200 | E6: =IFERROR(C6/D6,0) -> 0.5 | F6: =SUMIF(Portfolio_Master!$C$5:$C$12,A6,Portfolio_Master!$E$5:$E$12) -> 305 | G6: =COUNTIFS(Portfolio_Master!$C$5:$C$12,A6,Portfolio_Master!$M$5:$M$12,"<>Low") -> 2 | H6: =REPT("█",ROUND(E6*20,0)) -> ██████████
A7: Italy | B7: =COUNTIF(Portfolio_Master!$C$5:$C$12,A7) -> 1 | C7: =SUMIF(Portfolio_Master!$C$5:$C$12,A7,Portfolio_Master!$H$5:$H$12) -> 44 | D7: =SUMIF(Portfolio_Master!$C$5:$C$12,A7,Portfolio_Master!$I$5:$I$12) -> 100 | E7: =IFERROR(C7/D7,0) -> 0.44 | F7: =SUMIF(Portfolio_Master!$C$5:$C$12,A7,Portfolio_Master!$E$5:$E$12) -> 110 | G7: =COUNTIFS(Portfolio_Master!$C$5:$C$12,A7,Portfolio_Master!$M$5:$M$12,"<>Low") -> 1 | H7: =REPT("█",ROUND(E7*20,0)) -> █████████
A8: Netherlands | B8: =COUNTIF(Portfolio_Master!$C$5:$C$12,A8) -> 1 | C8: =SUMIF(Portfolio_Master!$C$5:$C$12,A8,Portfolio_Master!$H$5:$H$12) -> 30 | D8: =SUMIF(Portfolio_Master!$C$5:$C$12,A8,Portfolio_Master!$I$5:$I$12) -> 100 | E8: =IFERROR(C8/D8,0) -> 0.3 | F8: =SUMIF(Portfolio_Master!$C$5:$C$12,A8,Portfolio_Master!$E$5:$E$12) -> 80 | G8: =COUNTIFS(Portfolio_Master!$C$5:$C$12,A8,Portfolio_Master!$M$5:$M$12,"<>Low") -> 1 | H8: =REPT("█",ROUND(E8*20,0)) -> ██████
A9: Poland | B9: =COUNTIF(Portfolio_Master!$C$5:$C$12,A9) -> 1 | C9: =SUMIF(Portfolio_Master!$C$5:$C$12,A9,Portfolio_Master!$H$5:$H$12) -> 44 | D9: =SUMIF(Portfolio_Master!$C$5:$C$12,A9,Portfolio_Master!$I$5:$I$12) -> 100 | E9: =IFERROR(C9/D9,0) -> 0.44 | F9: =SUMIF(Portfolio_Master!$C$5:$C$12,A9,Portfolio_Master!$E$5:$E$12) -> 130 | G9: =COUNTIFS(Portfolio_Master!$C$5:$C$12,A9,Portfolio_Master!$M$5:$M$12,"<>Low") -> 0 | H9: =REPT("█",ROUND(E9*20,0)) -> █████████
A10: Spain | B10: =COUNTIF(Portfolio_Master!$C$5:$C$12,A10) -> 2 | C10: =SUMIF(Portfolio_Master!$C$5:$C$12,A10,Portfolio_Master!$H$5:$H$12) -> 154 | D10: =SUMIF(Portfolio_Master!$C$5:$C$12,A10,Portfolio_Master!$I$5:$I$12) -> 200 | E10: =IFERROR(C10/D10,0) -> 0.77 | F10: =SUMIF(Portfolio_Master!$C$5:$C$12,A10,Portfolio_Master!$E$5:$E$12) -> 395 | G10: =COUNTIFS(Portfolio_Master!$C$5:$C$12,A10,Portfolio_Master!$M$5:$M$12,"<>Low") -> 1 | H10: =REPT("█",ROUND(E10*20,0)) -> ███████████████
A12: State / Region Progress
A13: Country | B13: State | C13: Projects | D13: Completed_Weight | E13: Total_Weight | F13: Weighted_Progress_% | G13: MW_Pipeline | H13: Delayed_Projects | I13: Progress_Bar
A14: France | B14: Occitanie | C14: =COUNTIFS(Portfolio_Master!$C$5:$C$12,A14,Portfolio_Master!$D$5:$D$12,B14) -> 1 | D14: =SUMIFS(Portfolio_Master!$H$5:$H$12,Portfolio_Master!$C$5:$C$12,A14,Portfolio_Master!$D$5:$D$12,B14) -> 100 | E14: =SUMIFS(Portfolio_Master!$I$5:$I$12,Portfolio_Master!$C$5:$C$12,A14,Portfolio_Master!$D$5:$D$12,B14) -> 100 | F14: =IFERROR(D14/E14,0) -> 1 | G14: =SUMIFS(Portfolio_Master!$E$5:$E$12,Portfolio_Master!$C$5:$C$12,A14,Portfolio_Master!$D$5:$D$12,B14) -> 95 | H14: =COUNTIFS(Portfolio_Master!$C$5:$C$12,A14,Portfolio_Master!$D$5:$D$12,B14,Portfolio_Master!$M$5:$M$12,"<>Low") -> 0 | I14: =REPT("█",ROUND(F14*20,0)) -> ████████████████████
A15: Germany | B15: Brandenburg | C15: =COUNTIFS(Portfolio_Master!$C$5:$C$12,A15,Portfolio_Master!$D$5:$D$12,B15) -> 1 | D15: =SUMIFS(Portfolio_Master!$H$5:$H$12,Portfolio_Master!$C$5:$C$12,A15,Portfolio_Master!$D$5:$D$12,B15) -> 64 | E15: =SUMIFS(Portfolio_Master!$I$5:$I$12,Portfolio_Master!$C$5:$C$12,A15,Portfolio_Master!$D$5:$D$12,B15) -> 100 | F15: =IFERROR(D15/E15,0) -> 0.64 | G15: =SUMIFS(Portfolio_Master!$E$5:$E$12,Portfolio_Master!$C$5:$C$12,A15,Portfolio_Master!$D$5:$D$12,B15) -> 145 | H15: =COUNTIFS(Portfolio_Master!$C$5:$C$12,A15,Portfolio_Master!$D$5:$D$12,B15,Portfolio_Master!$M$5:$M$12,"<>Low") -> 1 | I15: =REPT("█",ROUND(F15*20,0)) -> █████████████
A16: Germany | B16: Saxony | C16: =COUNTIFS(Portfolio_Master!$C$5:$C$12,A16,Portfolio_Master!$D$5:$D$12,B16) -> 1 | D16: =SUMIFS(Portfolio_Master!$H$5:$H$12,Portfolio_Master!$C$5:$C$12,A16,Portfolio_Master!$D$5:$D$12,B16) -> 36 | E16: =SUMIFS(Portfolio_Master!$I$5:$I$12,Portfolio_Master!$C$5:$C$12,A16,Portfolio_Master!$D$5:$D$12,B16) -> 100 | F16: =IFERROR(D16/E16,0) -> 0.36 | G16: =SUMIFS(Portfolio_Master!$E$5:$E$12,Portfolio_Master!$C$5:$C$12,A16,Portfolio_Master!$D$5:$D$12,B16) -> 160 | H16: =COUNTIFS(Portfolio_Master!$C$5:$C$12,A16,Portfolio_Master!$D$5:$D$12,B16,Portfolio_Master!$M$5:$M$12,"<>Low") -> 1 | I16: =REPT("█",ROUND(F16*20,0)) -> ███████
A17: Italy | B17: Sicily | C17: =COUNTIFS(Portfolio_Master!$C$5:$C$12,A17,Portfolio_Master!$D$5:$D$12,B17) -> 1 | D17: =SUMIFS(Portfolio_Master!$H$5:$H$12,Portfolio_Master!$C$5:$C$12,A17,Portfolio_Master!$D$5:$D$12,B17) -> 44 | E17: =SUMIFS(Portfolio_Master!$I$5:$I$12,Portfolio_Master!$C$5:$C$12,A17,Portfolio_Master!$D$5:$D$12,B17) -> 100 | F17: =IFERROR(D17/E17,0) -> 0.44 | G17: =SUMIFS(Portfolio_Master!$E$5:$E$12,Portfolio_Master!$C$5:$C$12,A17,Portfolio_Master!$D$5:$D$12,B17) -> 110 | H17: =COUNTIFS(Portfolio_Master!$C$5:$C$12,A17,Portfolio_Master!$D$5:$D$12,B17,Portfolio_Master!$M$5:$M$12,"<>Low") -> 1 | I17: =REPT("█",ROUND(F17*20,0)) -> █████████
A18: Netherlands | B18: North Holland | C18: =COUNTIFS(Portfolio_Master!$C$5:$C$12,A18,Portfolio_Master!$D$5:$D$12,B18) -> 1 | D18: =SUMIFS(Portfolio_Master!$H$5:$H$12,Portfolio_Master!$C$5:$C$12,A18,Portfolio_Master!$D$5:$D$12,B18) -> 30 | E18: =SUMIFS(Portfolio_Master!$I$5:$I$12,Portfolio_Master!$C$5:$C$12,A18,Portfolio_Master!$D$5:$D$12,B18) -> 100 | F18: =IFERROR(D18/E18,0) -> 0.3 | G18: =SUMIFS(Portfolio_Master!$E$5:$E$12,Portfolio_Master!$C$5:$C$12,A18,Portfolio_Master!$D$5:$D$12,B18) -> 80 | H18: =COUNTIFS(Portfolio_Master!$C$5:$C$12,A18,Portfolio_Master!$D$5:$D$12,B18,Portfolio_Master!$M$5:$M$12,"<>Low") -> 1 | I18: =REPT("█",ROUND(F18*20,0)) -> ██████
A19: Poland | B19: Lower Silesia | C19: =COUNTIFS(Portfolio_Master!$C$5:$C$12,A19,Portfolio_Master!$D$5:$D$12,B19) -> 1 | D19: =SUMIFS(Portfolio_Master!$H$5:$H$12,Portfolio_Master!$C$5:$C$12,A19,Portfolio_Master!$D$5:$D$12,B19) -> 44 | E19: =SUMIFS(Portfolio_Master!$I$5:$I$12,Portfolio_Master!$C$5:$C$12,A19,Portfolio_Master!$D$5:$D$12,B19) -> 100 | F19: =IFERROR(D19/E19,0) -> 0.44 | G19: =SUMIFS(Portfolio_Master!$E$5:$E$12,Portfolio_Master!$C$5:$C$12,A19,Portfolio_Master!$D$5:$D$12,B19) -> 130 | H19: =COUNTIFS(Portfolio_Master!$C$5:$C$12,A19,Portfolio_Master!$D$5:$D$12,B19,Portfolio_Master!$M$5:$M$12,"<>Low") -> 0 | I19: =REPT("█",ROUND(F19*20,0)) -> █████████
A20: Spain | B20: Andalusia | C20: =COUNTIFS(Portfolio_Master!$C$5:$C$12,A20,Portfolio_Master!$D$5:$D$12,B20) -> 1 | D20: =SUMIFS(Portfolio_Master!$H$5:$H$12,Portfolio_Master!$C$5:$C$12,A20,Portfolio_Master!$D$5:$D$12,B20) -> 54 | E20: =SUMIFS(Portfolio_Master!$I$5:$I$12,Portfolio_Master!$C$5:$C$12,A20,Portfolio_Master!$D$5:$D$12,B20) -> 100 | F20: =IFERROR(D20/E20,0) -> 0.54 | G20: =SUMIFS(Portfolio_Master!$E$5:$E$12,Portfolio_Master!$C$5:$C$12,A20,Portfolio_Master!$D$5:$D$12,B20) -> 220 | H20: =COUNTIFS(Portfolio_Master!$C$5:$C$12,A20,Portfolio_Master!$D$5:$D$12,B20,Portfolio_Master!$M$5:$M$12,"<>Low") -> 1 | I20: =REPT("█",ROUND(F20*20,0)) -> ███████████
A21: Spain | B21: Valencia | C21: =COUNTIFS(Portfolio_Master!$C$5:$C$12,A21,Portfolio_Master!$D$5:$D$12,B21) -> 1 | D21: =SUMIFS(Portfolio_Master!$H$5:$H$12,Portfolio_Master!$C$5:$C$12,A21,Portfolio_Master!$D$5:$D$12,B21) -> 100 | E21: =SUMIFS(Portfolio_Master!$I$5:$I$12,Portfolio_Master!$C$5:$C$12,A21,Portfolio_Master!$D$5:$D$12,B21) -> 100 | F21: =IFERROR(D21/E21,0) -> 1 | G21: =SUMIFS(Portfolio_Master!$E$5:$E$12,Portfolio_Master!$C$5:$C$12,A21,Portfolio_Master!$D$5:$D$12,B21) -> 175 | H21: =COUNTIFS(Portfolio_Master!$C$5:$C$12,A21,Portfolio_Master!$D$5:$D$12,B21,Portfolio_Master!$M$5:$M$12,"<>Low") -> 0 | I21: =REPT("█",ROUND(F21*20,0)) -> ████████████████████

Sheet Insights
A1: ALAS Energy | Controller Insights
A3: Insight Area | B3: Formula-Linked Statement | C3: Use Case
A4: Portfolio health | B4: =IF(AVERAGE(Portfolio_Master!$J$5:$J$12)>=0.75,"Portfolio weighted progress is strong overall","Portfolio weighted progress indicates meaningful execution risk remains") -> Portfolio weighted progress indicates meaningful execution risk remains | C4: Dashboard summary
A5: Delay focus | B5: =COUNTIF(Portfolio_Master!$M$5:$M$12,"High")&" projects show high risk based on delay impact and require management attention." -> 2 projects show high risk based on delay impact and require management attention. | C5: Escalation note
A6: Budget pressure | B6: =COUNTIF(Portfolio_Master!$T$5:$T$12,"Over Budget")&" projects are consuming budget faster than weighted progress." -> 6 projects are consuming budget faster than weighted progress. | C6: Controller commentary
A7: Geography signal | B7: =INDEX(Geography_Progress!$A$5:$A$9,MATCH(MAX(Geography_Progress!$E$5:$E$9),Geography_Progress!$E$5:$E$9,0))&" currently has the strongest weighted country-level progress." -> France currently has the strongest weighted country-level progress. | C7: Country spotlight
A8: Project spotlight | B8: =INDEX(Portfolio_Master!$B$5:$B$12,MATCH(MAX(Portfolio_Master!$O$5:$O$12),Portfolio_Master!$O$5:$O$12,0))&" leads on risk-adjusted progress." -> Occitanie Ground Mount leads on risk-adjusted progress. | C8: Management review

Sheet Dashboard
A1: ALAS Energy | Portfolio Control Tower
A2: Controller-level view of weighted progress, risk-adjusted performance, delay impact, budget efficiency, and geography progress.
A4: Total Projects =COUNTA(Portfolio_Master!A5:A12) | E4: MW Pipeline =SUM(Portfolio_Master!E5:E12) | I4: Weighted Progress =AVERAGE(Portfolio_Master!J5:J12)
A8: Risk-Adjusted Progress =AVERAGE(Portfolio_Master!O5:O12) | E8: High Risk Projects =COUNTIF(Portfolio_Master!M5:M12,"High") | I8: Over Budget Projects =COUNTIF(Portfolio_Master!T5:T12,"Over Budget")
A15: Project | B15: Progress_% | C15: Risk_Adjusted_Progress | D15: Budget_Used_% | F15: Stage | G15: Projects | I15: Country | J15: Weighted_Progress
A16: =Portfolio_Master!B5 -> Brandenburg Solar Park | B16: =Portfolio_Master!J5 -> 0.64 | C16: =Portfolio_Master!O5 -> 0.48 | D16: =Portfolio_Master!R5 -> 0.95 | F16: Development | G16: =COUNTIF(Portfolio_Master!$F$5:$F$12,F16) -> 3 | I16: =Geography_Progress!A5 -> France | J16: =Geography_Progress!E5 -> 1
A17: =Portfolio_Master!B6 -> Andalusia Solar Cluster | B17: =Portfolio_Master!J6 -> 0.54 | C17: =Portfolio_Master!O6 -> 0.486 | D17: =Portfolio_Master!R6 -> 1.0424242 | F17: Construction | G17: =COUNTIF(Portfolio_Master!$F$5:$F$12,F17) -> 3 | I17: =Geography_Progress!A6 -> Germany | J17: =Geography_Progress!E6 -> 0.5
A18: =Portfolio_Master!B7 -> Sicily Agrivoltaic Hub | B18: =Portfolio_Master!J7 -> 0.44 | C18: =Portfolio_Master!O7 -> 0.396 | D18: =Portfolio_Master!R7 -> 1.0425532 | F18: Active | G18: =COUNTIF(Portfolio_Master!$F$5:$F$12,F18) -> 2 | I18: =Geography_Progress!A7 -> Italy | J18: =Geography_Progress!E7 -> 0.44
A19: =Portfolio_Master!B8 -> Occitanie Ground Mount | B19: =Portfolio_Master!J8 -> 1 | C19: =Portfolio_Master!O8 -> 1 | D19: =Portfolio_Master!R8 -> 0.98780488 | I19: =Geography_Progress!A8 -> Netherlands | J19: =Geography_Progress!E8 -> 0.3
A20: =Portfolio_Master!B9 -> North Holland Solar Farm | B20: =Portfolio_Master!J9 -> 0.3 | C20: =Portfolio_Master!O9 -> 0.225 | D20: =Portfolio_Master!R9 -> 0.98529412 | I20: =Geography_Progress!A9 -> Poland | J20: =Geography_Progress!E9 -> 0.44
A21: =Portfolio_Master!B10 -> Lower Silesia PV Project | B21: =Portfolio_Master!J10 -> 0.44 | C21: =Portfolio_Master!O10 -> 0.44 | D21: =Portfolio_Master!R10 -> 1.0693069 | F21: Risk_Level | G21: Projects | I21: =Geography_Progress!A10 -> Spain | J21: =Geography_Progress!E10 -> 0.77
A22: =Portfolio_Master!B11 -> Saxony Battery-Ready PV | B22: =Portfolio_Master!J11 -> 0.36 | C22: =Portfolio_Master!O11 -> 0.324 | D22: =Portfolio_Master!R11 -> 0.97619048 | F22: Low | G22: =COUNTIF(Portfolio_Master!$M$5:$M$12,F22) -> 3
A23: =Portfolio_Master!B12 -> Valencia Hybrid Solar Site | B23: =Portfolio_Master!J12 -> 1 | C23: =Portfolio_Master!O12 -> 1 | D23: =Portfolio_Master!R12 -> 0.98529412 | F23: Medium | G23: =COUNTIF(Portfolio_Master!$M$5:$M$12,F23) -> 3
F24: High | G24: =COUNTIF(Portfolio_Master!$M$5:$M$12,F24) -> 2
